Workbook
Name AP_Namen: Ansprechpartner!$E$4:$E$80
Name Gewerke_Liste: 'Gewerke & Kabeltypen'!$A$4:$A$150
Name Kabeltypen_Liste: 'Gewerke & Kabeltypen'!$C$4:$C$150
Name Strecken_BA1: Streckennummern!$A$5:$A$51
Name Strecken_BA2: Streckennummern!$C$5:$C$51
Name Strecken_BA3: Streckennummern!$E$5:$E$51

Sheet Einsatzplanung 
A1: WUS-BST-2132 – Einsatzplanung Kabelbereitschaft 2026 | E1: Juli 2026 | Z1: August 2026 | BE1: September 2026 | CI1: Oktober 2026 | DN1: November 2026 | ER1: Dezember 2026
D2: NAME → | E2: 46214 | F2: 46215 | G2: 46216 | H2: 46217 | I2: 46218 | J2: 46219 | K2: 46220 | L2: 46221 | M2: 46222 | N2: 46223 | O2: 46224 | P2: 46225 | Q2: 46226 | R2: 46227 | S2: 46228 | T2: 46229 | U2: 46230 | V2: 46231 | W2: 46232 | X2: 46233 | Y2: 46234 | Z2: 46235 | AA2: 46236 | AB2: 46237 | AC2: 46238 | AD2: 46239 | AE2: 46240 | AF2: 46241 | AG2: 46242 | AH2: 46243 | AI2: 46244 | AJ2: 46245 | AK2: 46246 | AL2: 46247 | AM2: 46248 | AN2: 46249 | AO2: 46250 | AP2: 46251 | AQ2: 46252 | AR2: 46253 | AS2: 46254 | AT2: 46255 | AU2: 46256 | AV2: 46257 | AW2: 46258 | AX2: 46259 | AY2: 46260 | AZ2: 46261 | BA2: 46262 | BB2: 46263 | BC2: 46264 | BD2: 46265 | BE2: 46266 | BF2: 46267 | BG2: 46268 | BH2: 46269 | BI2: 46270 | BJ2: 46271 | BK2: 46272 | BL2: 46273 | BM2: 46274 | BN2: 46275 | BO2: 46276 | BP2: 46277 | BQ2: 46278 | BR2: 46279 | BS2: 46280 | BT2: 46281 | BU2: 46282 | BV2: 46283 | BW2: 46284 | BX2: 46285 | BY2: 46286 | BZ2: 46287 | CA2: 46288 | CB2: 46289 | CC2: 46290 | CD2: 46291 | CE2: 46292 | CF2: 46293 | CG2: 46294 | CH2: 46295 | CI2: 46296 | CJ2: 46297 | CK2: 46298 | CL2: 46299 | CM2: 46300 | CN2: 46301 | CO2: 46302 | CP2: 46303 | CQ2: 46304 | CR2: 46305 | CS2: 46306 | CT2: 46307 | CU2: 46308 | CV2: 46309 | CW2: 46310 | CX2: 46311 | CY2: 46312 | CZ2: 46313 | DA2: 46314 | DB2: 46315 | DC2: 46316 | DD2: 46317 | DE2: 46318 | DF2: 46319 | DG2: 46320 | DH2: 46321 | DI2: 46322 | DJ2: 46323 | DK2: 46324 | DL2: 46325 | DM2: 46326 | DN2: 46327 | DO2: 46328 | DP2: 46329 | DQ2: 46330 | DR2: 46331 | DS2: 46332 | DT2: 46333 | DU2: 46334 | DV2: 46335 | DW2: 46336 | DX2: 46337 | DY2: 46338 | DZ2: 46339 | EA2: 46340 | EB2: 46341 | EC2: 46342 | ED2: 46343 | EE2: 46344 | EF2: 46345 | EG2: 46346 | EH2: 46347 | EI2: 46348 | EJ2: 46349 | EK2: 46350 | EL2: 46351 | EM2: 46352 | EN2: 46353 | EO2: 46354 | EP2: 46355 | EQ2: 46356 | ER2: 46357 | ES2: 46358 | ET2: 46359 | EU2: 46360 | EV2: 46361 | EW2: 46362 | EX2: 46363 | EY2: 46364 | EZ2: 46365 | FA2: 46366 | FB2: 46367 | FC2: 46368 | FD2: 46369 | FE2: 46370 | FF2: 46371
E3: Sa | F3: So | G3: Mo | H3: Di | I3: Mi | J3: Do | K3: Fr | L3: Sa | M3: So | N3: Mo | O3: Di | P3: Mi | Q3: Do | R3: Fr | S3: Sa | T3: So | U3: Mo | V3: Di | W3: Mi | X3: Do | Y3: Fr | Z3: Sa | AA3: So | AB3: Mo | AC3: Di | AD3: Mi | AE3: Do | AF3: Fr | AG3: Sa | AH3: So | AI3: Mo | AJ3: Di | AK3: Mi | AL3: Do | AM3: Fr | AN3: Sa | AO3: So | AP3: Mo | AQ3: Di | AR3: Mi | AS3: Do | AT3: Fr | AU3: Sa | AV3: So | AW3: Mo | AX3: Di | AY3: Mi | AZ3: Do | BA3: Fr | BB3: Sa | BC3: So | BD3: Mo | BE3: Di | BF3: Mi | BG3: Do | BH3: Fr | BI3: Sa | BJ3: So | BK3: Mo | BL3: Di | BM3: Mi | BN3: Do | BO3: Fr | BP3: Sa | BQ3: So | BR3: Mo | BS3: Di | BT3: Mi | BU3: Do | BV3: Fr | BW3: Sa | BX3: So | BY3: Mo | BZ3: Di | CA3: Mi | CB3: Do | CC3: Fr | CD3: Sa | CE3: So | CF3: Mo | CG3: Di | CH3: Mi | CI3: Do | CJ3: Fr | CK3: Sa | CL3: So | CM3: Mo | CN3: Di | CO3: Mi | CP3: Do | CQ3: Fr | CR3: Sa | CS3: So | CT3: Mo | CU3: Di | CV3: Mi | CW3: Do | CX3: Fr | CY3: Sa | CZ3: So | DA3: Mo | DB3: Di | DC3: Mi | DD3: Do | DE3: Fr | DF3: Sa | DG3: So | DH3: Mo | DI3: Di | DJ3: Mi | DK3: Do | DL3: Fr | DM3: Sa | DN3: So | DO3: Mo | DP3: Di | DQ3: Mi | DR3: Do | DS3: Fr | DT3: Sa | DU3: So | DV3: Mo | DW3: Di | DX3: Mi | DY3: Do | DZ3: Fr | EA3: Sa | EB3: So | EC3: Mo | ED3: Di | EE3: Mi | EF3: Do | EG3: Fr | EH3: Sa | EI3: So | EJ3: Mo | EK3: Di | EL3: Mi | EM3: Do | EN3: Fr | EO3: Sa | EP3: So | EQ3: Mo | ER3: Di | ES3: Mi | ET3: Do | EU3: Fr | EV3: Sa | EW3: So | EX3: Mo | EY3: Di | EZ3: Mi | FA3: Do | FB3: Fr | FC3: Sa | FD3: So | FE3: Mo | FF3: Di
A4: BA 1 | E4: PS | F4: PS | G4: JM | H4: JM | I4: JM | J4: JM | K4: JM | L4: JM | M4: JM | N4: PR | O4: PR | P4: PR | Q4: PR | R4: TG | S4: TG | T4: TZ | U4: TZ | V4: TZ | W4: TZ | X4: TZ | Y4: TZ | Z4: TZ | AA4: TZ | AB4: SE | AC4: SE | AD4: SE | AE4: SE | AF4: SE | AG4: KAB2 | AH4: KAB2 | AI4: SE | AJ4: SE | AK4: SE | AL4: SE | AM4: SE | AN4: SE | AO4: SE | AP4: AW | AQ4: AW | AR4: AW | AS4: AW | AT4: AW | AY4: SE | AZ4: SE
F5: SS | G5: TG | H5: TG | I5: TG | J5: TG | N5: TS | O5: TS | P5: TS | Q5: TS | R5: TS | S5: TS | U5: TS | V5: TS | W5: TS | X5: TS | Y5: TS | Z5: TS | AA5: TS | AC5: KAB 2 | AD5: KAB 2 | AE5: KAB 2 | AF5: KAB 2 | AG5: AW | AH5: AW | AI5: KAB2 | AJ5: KAB2 | AK5: KAB2 | AL5: KAB2 | AM5: KAB2 | AN5: KAB2 | AO5: KAB2 | AP5: KAB2 | AQ5: KAB2 | AY5: AW | AZ5: AW
A6: BA 2 | N6: JM | O6: JM | P6: JM | Q6: JM | R6: JM | S6: JM | T6: JM | U6: AK | V6: AK | W6: AK | X6: AK | Y6: AK | Z6: AK | AA6: AK | AB6: SP | AC6: KAB1 | AD6: KAB1 | AE6: KAB1 | AF6: KAB1 | AG6: KAB1 | AH6: KAB1 | AI6: KAB1 | AJ6: KAB1 | AK6: KAB1 | AL6: KAB1 | AM6: KAB1 | AN6: KAB1 | AO6: KAB1
N7: IM | O7: IM | P7: IM | Q7: IM | R7: IM | S7: IM | T7: IM | U7: IM | V7: IM | W7: IM | X7: IM | Y7: IM | Z7: IM | AA7: IM | AB7: SL | AC7: SL | AD7: SL | AE7: SL | AF7: SL | AG7: SL | AH7: SL | AI7: SL | AJ7: SL | AK7: SL | AL7: SL | AM7: SL | AN7: SL | AO7: SL
A8: BA 3 | E8: PS | F8: SS | G8: TG | H8: TG | I8: TG | J8: TG | N8: IM | O8: IM | P8: IM | Q8: IM | R8: IM | S8: IM | T8: IM | U8: IM | V8: EM | W8: KE | X8: KE | Y8: KE | Z8: PC | AA8: PC | AC8: SP | AD8: SP | AE8: SP | AF8: SP | AG8: SP | AH8: BA2 macht auch BA3 | AI8: BA2 macht auch BA3 | AJ8: SS | AK8: SS | AL8: SS | AM8: SS | AN8: SS
F9: PS | G9: JM | H9: JM | I9: JM | J9: JM | K9: JM | L9: JM | M9: JM | N9: JM | O9: JM | P9: JM | Q9: JM | R9: JM | S9: JM | T9: JM | U9: PR | V9: PR | W9: PR | X9: PR bis 13:00 | Y9: PR | Z9: PR | AA9: PR | AB9: TS | AC9: TS | AD9: TS | AE9: TS | AF9: BM | AG9: MB | AH9: MB | AI9: BA2 macht auch BA3 | AJ9: MI | AK9: MI | AL9: MI | AM9: MI | AN9: MI
A11: Namensliste – neue Namen unten eintragen, Kürzel wird automatisch erzeugt (Vorname- + Nachname-Initial). Doppelte Kürzel werden rot markiert → dann Kürzel von Hand überschreiben.
A12: Nachname | B12: Vorname | C12: Kürzel | D12: Notiz
A13: Goscianiak | B13: Timo | C13: =IF(OR($A13="",$B13=""),"",UPPER(LEFT($B13,1)&LEFT($A13,1))) -> TG
A14: Schymik | B14: Peter | C14: =IF(OR($A14="",$B14=""),"",UPPER(LEFT($B14,1)&LEFT($A14,1))) -> PS
A15: Vojnkovic | B15: Amer | C15: =IF(OR($A15="",$B15=""),"",UPPER(LEFT($B15,1)&LEFT($A15,1))) -> AV
A16: Meier | B16: Jürgen | C16: =IF(OR($A16="",$B16=""),"",UPPER(LEFT($B16,1)&LEFT($A16,1))) -> JM | D16: Auto ehem. Ehmke ohne Werkzeug WS 1091
A17: Marsch | B17: Christian | C17: =IF(OR($A17="",$B17=""),"",UPPER(LEFT($B17,1)&LEFT($A17,1))) -> CM
A18: Kühnhold | B18: Dennis | C18: =IF(OR($A18="",$B18=""),"",UPPER(LEFT($B18,1)&LEFT($A18,1))) -> DK
A19: Retzlaff | B19: Pascal | C19: =IF(OR($A19="",$B19=""),"",UPPER(LEFT($B19,1)&LEFT($A19,1))) -> PR
A20: Schechtow | B20: Sergej | C20: =IF(OR($A20="",$B20=""),"",UPPER(LEFT($B20,1)&LEFT($A20,1))) -> SS
A21: Markitin | B21: Igor | C21: =IF(OR($A21="",$B21=""),"",UPPER(LEFT($B21,1)&LEFT($A21,1))) -> IM
A22: Cvrlje | B22: Ivan | C22: =IF(OR($A22="",$B22=""),"",UPPER(LEFT($B22,1)&LEFT($A22,1))) -> IC
A23: Stempel | B23: Timo | C23: =IF(OR($A23="",$B23=""),"",UPPER(LEFT($B23,1)&LEFT($A23,1))) -> TS
A24: Zöller | B24: Timon | C24: =IF(OR($A24="",$B24=""),"",UPPER(LEFT($B24,1)&LEFT($A24,1))) -> TZ
A25: Seebold | B25: Sebastian | C25: SE
A26: Klimakov | B26: Artem | C26: =IF(OR($A26="",$B26=""),"",UPPER(LEFT($B26,1)&LEFT($A26,1))) -> AK
A27: Mujezinovic | B27: Elvin | C27: =IF(OR($A27="",$B27=""),"",UPPER(LEFT($B27,1)&LEFT($A27,1))) -> EM
A28: Hallmann | B28: Timo | C28: =IF(OR($A28="",$B28=""),"",UPPER(LEFT($B28,1)&LEFT($A28,1))) -> TH
A29: Karaeli | B29: Emre | C29: KE
A30: Czernik | B30: Peter | C30: =IF(OR($A30="",$B30=""),"",UPPER(LEFT($B30,1)&LEFT($A30,1))) -> PC
A31: Lesnikov | B31: Sergej | C31: =IF(OR($A31="",$B31=""),"",UPPER(LEFT($B31,1)&LEFT($A31,1))) -> SL
A32: Woodfin | B32: Andreas | C32: =IF(OR($A32="",$B32=""),"",UPPER(LEFT($B32,1)&LEFT($A32,1))) -> AW
A33: KAB 1 | C33: KAB 1
A34: KAB 2 | C34: KAB 2
A35: Srokowski | B35: Pawel | C35: SP | D35: Auto ehm. Gümüs
A36: Becker | B36: Maurice | C36: =IF(OR($A36="",$B36=""),"",UPPER(LEFT($B36,1)&LEFT($A36,1))) -> MB
A37: Breuer | B37: Markus | C37: BM
A38: Maksimenko | B38: Ihor | C38: MI
C39: =IF(OR($A39="",$B39=""),"",UPPER(LEFT($B39,1)&LEFT($A39,1)))
C40: =IF(OR($A40="",$B40=""),"",UPPER(LEFT($B40,1)&LEFT($A40,1)))
C41: =IF(OR($A41="",$B41=""),"",UPPER(LEFT($B41,1)&LEFT($A41,1)))
...

Sheet BA1
A1: Kabelbereitschaft – Bauabschnitt 1
A2: Erledigt = „Ja“ → Zeile grün | In Klärung = „✔“ → Zeile gelb | Tag, Funktion, Telefonnummer automatisch | „Anzahl Kabel“ > 1 eintragen und Skript „Kabel-Unterzeilen erzeugen“ (Register Automatisieren) ausführen → Unterzeilen a/b/c werden eingefügt und auf-/zuklappbar gruppiert | Streckenkilometer ist Pflichtfeld | Blaue Einträge = aus Postfach
A3: Meldung | N3: Bearbeitung
A4: Lfd. Nr. | B4: Datum | C4: Tag | D4: Uhrzeit | E4: Anrufender | F4: Funktion des Anrufenden | G4: Telefonnummer | H4: Streckennummer | I4: Ortschaft | J4: Anlage (optional) | K4: Streckenkilometer | L4: Anzahl Kabel | M4: Meldung | N4: Annahme Datum | O4: Annahme Uhrzeit | P4: Mitarbeiter | Q4: Gewerk | R4: Kabeltyp | S4: Sachstand | T4: Notwendige Maßnahmen | U4: Erledigt (Ja/Nein) | V4: In Klärung (✔)
A5: 1 | B5: 46220 | C5: =IF(B5="","",CHOOSE(WEEKDAY(B5,2),"Montag","Dienstag","Mittwoch","Donnerstag","Freitag","Samstag","Sonntag")) -> Freitag | D5: 0.31597222 | E5: Kräner | F5: BÜW | G5: 015750662038 | H5: 3507 | I5: Rüdesheim | J5: BÜ 94 | K5: 65.26 | M5: Gerissene Kabel, Schadstelle muss aufgenommen werden | N5: 46220 | O5: 0.35416667 | P5: J.Meier | S5: Kabel aufgenommen | T5: Proversorisch verschlossen | V5: ✔
A6: 2 | B6: 46222 | C6: =IF(B6="","",CHOOSE(WEEKDAY(B6,2),"Montag","Dienstag","Mittwoch","Donnerstag","Freitag","Samstag","Sonntag")) -> Sonntag | D6: 0.42916667 | E6: Pachonik, Leon | F6: BÜW | G6: 01522712662 | H6: 3507 | I6: Rüdesheim | J6: BÜ 94 | K6: 65.1 | M6: TK Kabel gerissen | N6: 46222 | O6: 0.5 | P6: J. Meier | S6: DEFEKT 10 adriges TK | T6: Kabelschaden instandgesetzt
A7: 3 | B7: 46222 | C7: =IF(B7="","",CHOOSE(WEEKDAY(B7,2),"Montag","Dienstag","Mittwoch","Donnerstag","Freitag","Samstag","Sonntag")) -> Sonntag | D7: 0.45902778 | E7: Fr. Esten | F7: BÜW | G7: 015758316071 | H7: 3507 | I7: Biebrich | J7: LSW | K7: 39,4-39,2 | M7: Kabelschaden ca. 0.5 m von LSW entfernt, ggf weitere Schadstellen | N7: 46222 | O7: 0.63263889 | P7: J. Meier | S7: Altes Ölkabel, 50er Jahre, wohlmöglich nicht in Betrieb, weiteres Jkabel | T7: Kabel nicht in Betrieb
A8: 4 | B8: 46222 | C8: =IF(B8="","",CHOOSE(WEEKDAY(B8,2),"Montag","Dienstag","Mittwoch","Donnerstag","Freitag","Samstag","Sonntag")) -> Sonntag | D8: 0.59583333 | E8: Pachonik, Leon | F8: BÜW | G8: 01522712662 | H8: 3507 | I8: Rüdesheim | J8: BÜ 94 | K8: 65.1 | M8: Kabel beschädigt, vermutlich EM | N8: 46222 | O8: 0.71875 | P8: J. Meier | S8: 3 Schadstellen beseitigt. | T8: Kabel gemufft
A9: 5 | B9: 46223 | C9: =IF(B9="","",CHOOSE(WEEKDAY(B9,2),"Montag","Dienstag","Mittwoch","Donnerstag","Freitag","Samstag","Sonntag")) -> Montag | D9: 0.39583333 | E9: Pachonik, Leon | F9: BÜW | G9: 01522712662 | H9: 3507 | I9: Rüdesheim | K9: 61.992 | M9: Kabel beschädigt, alt LST 130-150 adrig | N9: 46223 | O9: 0.34375 | P9: Retzlaff | S9: Mit BÜW Leon Pachonik befundet. Altes Kabel | T9: keine weitere Anwendung
A10: 6 | B10: 46224 | C10: =IF(B10="","",CHOOSE(WEEKDAY(B10,2),"Montag","Dienstag","Mittwoch","Donnerstag","Freitag","Samstag","Sonntag")) -> Dienstag | D10: 0.37847222 | E10: Altinos Emre | F10: BÜW | G10: 015224173988 | H10: 3507 | I10: Niederwalluf | K10: 43.6 | M10: Kabel sollte lediglich verschwenkt werden, | N10: 46223 | O10: 0.59791667 | P10: Retzlaff | S10: 2x Kabel verschwenkt, damit es nicht beschädigt wird | T10: erledigt | U10: Ja
A11: 7a | B11: 46224 | C11: =IF(B11="","",CHOOSE(WEEKDAY(B11,2),"Montag","Dienstag","Mittwoch","Donnerstag","Freitag","Samstag","Sonntag")) -> Dienstag | D11: 0.41736111 | E11: Fadime Esme | F11: LBÜW | G11: 01015758316071 | H11: 3507 | I11: Biebrich | J11: LSW | K11: 39.01-39.02 | L11: 2 | M11: Fund von 2 Kabeln, Foto geschickt | N11: 46224
A12: 7b | B12: 46224 | C12: =IF(B12="","",CHOOSE(WEEKDAY(B12,2),"Montag","Dienstag","Mittwoch","Donnerstag","Freitag","Samstag","Sonntag")) -> Dienstag | D12: 0.41736111 | E12: Fadime Esme | F12: LBÜW | G12: 01015758316071 | H12: 3507 | I12: Biebrich | J12: LSW | K12: 39.01-39.02 | M12: Fund von 2 Kabeln, Foto geschickt
A13: 8 | B13: 46224 | C13: =IF(B13="","",CHOOSE(WEEKDAY(B13,2),"Montag","Dienstag","Mittwoch","Donnerstag","Freitag","Samstag","Sonntag")) -> Dienstag | D13: 0.59166667 | E13: Müller | F13: BÜW | G13: 0171/3309584 | H13: 3507 | I13: Biebrich | J13: LSW | K13: 39.00 | M13: Kabelvorgefunden | N13: 46224
A14: 9 | B14: 46226 | C14: =IF(B14="","",CHOOSE(WEEKDAY(B14,2),"Montag","Dienstag","Mittwoch","Donnerstag","Freitag","Samstag","Sonntag")) -> Donnerstag | D14: 0.33333333 | E14: Pachonik, Leon | F14: BÜW | G14: 01522712662 | H14: 3507 | I14: Biebrich | K14: 39.1 | M14: AZ Ausbauen 345 II | N14: 46226 | O14: 0.37152778 | P14: Retzlaff | S14: AZ ausbauen | T14: AZ ausgebaut
A15: 10 | B15: 46226 | C15: =IF(B15="","",CHOOSE(WEEKDAY(B15,2),"Montag","Dienstag","Mittwoch","Donnerstag","Freitag","Samstag","Sonntag")) -> Donnerstag | D15: 0.61805556 | E15: Pachonik, Leon | F15: BÜW | G15: 01522712662 | H15: 3507 | I15: Eltville | K15: 48.464 | M15: Kabel von einem Signal | P15: Tim | S15: Geschnitten freigabe ALV 28.07.26 | T15: Erledigt | U15: Ja
A16: 11 | B16: 46228 | C16: =IF(B16="","",CHOOSE(WEEKDAY(B16,2),"Montag","Dienstag","Mittwoch","Donnerstag","Freitag","Samstag","Sonntag")) -> Samstag | D16: 0.68194444 | E16: Fadime Esne | F16: LBÜW | G16: +4915758316071 | H16: 3507 | I16: Biebrich | K16: 38.9 | M16: Kabel freigelegt nicht beschädigt | O16: 0.5 | P16: Zöller | T16: Erledigt | U16: Ja
A17: 12 | B17: 46228 | C17: =IF(B17="","",CHOOSE(WEEKDAY(B17,2),"Montag","Dienstag","Mittwoch","Donnerstag","Freitag","Samstag","Sonntag")) -> Samstag | D17: 0.68194444 | E17: Fadime Esne | F17: LBÜW | G17: +4915758316071 | H17: 3507 | I17: Biebrich | K17: 39 | M17: Kabel freigelegt nicht beschädigt unter der Bücke | O17: 0.5 | P17: Zöller | T17: Erledigt | U17: Ja
A18: 13a | B18: 46229 | C18: =IF(B18="","",CHOOSE(WEEKDAY(B18,2),"Montag","Dienstag","Mittwoch","Donnerstag","Freitag","Samstag","Sonntag")) -> Sonntag | D18: 0.49444444 | E18: Leon Pachonik | F18: BÜW | G18: +49152333533366 | H18: 3507 | I18: Niederwalluf | K18: 43.001 | L18: 5 | M18: 5 Kabel freigelegt Prüfen 1 Kabel Kunststoff | O18: 0.5 | P18: Zöller | S18: Kabel gehören nicht der DB AP: +4916097402441 Hicham Mountij | T18: Erledigt | U18: Ja
A19: 13b | B19: 46229 | C19: =IF(B19="","",CHOOSE(WEEKDAY(B19,2),"Montag","Dienstag","Mittwoch","Donnerstag","Freitag","Samstag","Sonntag")) -> Sonntag | D19: 0.49444444 | E19: Leon Pachonik | F19: BÜW | G19: +49152333533366 | H19: 3507 | I19: Niederwalluf | K19: 43.001 | M19: 5 Kabel freigelegt Prüfen 1 Kabel Kunststoff | Q19: Unbekannt | U19: Nein
A20: 13c | B20: 46229 | C20: =IF(B20="","",CHOOSE(WEEKDAY(B20,2),"Montag","Dienstag","Mittwoch","Donnerstag","Freitag","Samstag","Sonntag")) -> Sonntag | D20: 0.49444444 | E20: Leon Pachonik | F20: BÜW | G20: +49152333533366 | H20: 3507 | I20: Niederwalluf | K20: 43.001 | M20: 5 Kabel freigelegt Prüfen 1 Kabel Kunststoff
A21: 13d | B21: 46229 | C21: =IF(B21="","",CHOOSE(WEEKDAY(B21,2),"Montag","Dienstag","Mittwoch","Donnerstag","Freitag","Samstag","Sonntag")) -> Sonntag | D21: 0.49444444 | E21: Leon Pachonik | F21: BÜW | G21: +49152333533366 | H21: 3507 | I21: Niederwalluf | K21: 43.001 | M21: 5 Kabel freigelegt Prüfen 1 Kabel Kunststoff
A22: 13e | B22: 46229 | C22: =IF(B22="","",CHOOSE(WEEKDAY(B22,2),"Montag","Dienstag","Mittwoch","Donnerstag","Freitag","Samstag","Sonntag")) -> Sonntag | D22: 0.49444444 | E22: Leon Pachonik | F22: BÜW | G22: +49152333533366 | H22: 3507 | I22: Niederwalluf | K22: 43.001 | M22: 5 Kabel freigelegt Prüfen 1 Kabel Kunststoff
A23: 14 | B23: 46237 | C23: =IF(B23="","",CHOOSE(WEEKDAY(B23,2),"Montag","Dienstag","Mittwoch","Donnerstag","Freitag","Samstag","Sonntag")) -> Montag | D23: 0.6875 | E23: Natan Pernal | F23: BÜW | G23: +4915233326507 | H23: 3507 | I23: Rüdesheim | K23: 64.2 | M23: 2 Kabel prüfen Leon koordiniert | O23: 0.47916667 | P23: Seebold | S23: 04.08. Beide Kabel geschnitten durch Günter Zimmermann | T23: Erledigt | U23: Ja
A24: 15 | B24: 46238 | C24: =IF(B24="","",CHOOSE(WEEKDAY(B24,2),"Montag","Dienstag","Mittwoch","Donnerstag","Freitag","Samstag","Sonntag")) -> Dienstag | D24: 0.40069444 | E24: Leon Pachonik | F24: BÜW | G24: +49152333533366 | H24: 3507 | I24: Rüdesheim | J24: BÜ PO 93 | K24: 65.09 | M24: 3 Signalkabel zu klären | O24: 0.40208333 | P24: Seebold | S24: Alle kabel geschnitten durch Günter Zimmermann | T24: Erledigt | U24: Ja
A25: 16 | B25: 46238 | C25: =IF(B25="","",CHOOSE(WEEKDAY(B25,2),"Montag","Dienstag","Mittwoch","Donnerstag","Freitag","Samstag","Sonntag")) -> Dienstag | D25: 0.52430556 | E25: Leon Pachonik | F25: BÜW | G25: +49152333533366 | H25: 3507 | I25: Eltville | K25: 48.8 | M25: 1 signalkabel gefunden | O25: 0.52430556 | P25: Seebold | S25: Alle kabel geschnitten durch Günter Zimmermann | T25: Erledigt | U25: Ja
A26: 17 | B26: 46239 | C26: =IF(B26="","",CHOOSE(WEEKDAY(B26,2),"Montag","Dienstag","Mittwoch","Donnerstag","Freitag","Samstag","Sonntag")) -> Mittwoch | D26: 0.4625 | E26: Leon Pachonik | F26: BÜW | G26: +49152333533366 | H26: 3507 | I26: Rüdesheim | K26: 64.4 | M26: 4 Kabel gefunden | O26: 0.46180556 | P26: Seebold | S26: 4 Kabel gefenstert und wieder verschlossen
A27: 18 | B27: 46239 | C27: =IF(B27="","",CHOOSE(WEEKDAY(B27,2),"Montag","Dienstag","Mittwoch","Donnerstag","Freitag","Samstag","Sonntag")) -> Mittwoch | D27: 0.625 | E27: Leon Pachonik | F27: BÜW | G27: +49152333533366 | H27: 3507 | I27: Rüdesheim | K27: 50.8 | M27: Kabel aus PZB Verteil gerissen | O27: 0.64236111 | P27: Seebold | S27: Muss erneuert werden Verteiler Defekt
A28: 19 | B28: 46239 | C28: =IF(B28="","",CHOOSE(WEEKDAY(B28,2),"Montag","Dienstag","Mittwoch","Donnerstag","Freitag","Samstag","Sonntag")) -> Mittwoch | D28: 0.625 | E28: Leon Pachonik | F28: BÜW | G28: +49152333533366 | H28: 3507 | I28: Eltville | K28: 42.5 | M28: Kabel gefunden | O28: 0.63055556 | P28: Seebold | S28: Kabel gefenstert und wieder geschlossen
A29: 20 | B29: 46240 | C29: =IF(B29="","",CHOOSE(WEEKDAY(B29,2),"Montag","Dienstag","Mittwoch","Donnerstag","Freitag","Samstag","Sonntag")) -> Donnerstag | D29: 0.40902778 | E29: Leon Pachonik | F29: BÜW | G29: +49152333533366 | H29: 3507 | I29: Rüdesheim | K29: 65.856 | M29: Kabel gefunden | O29: 0.41666667 | P29: Seebold | S29: Kabel gefenstert und verschlossen
A30: 21 | B30: 46240 | C30: =IF(B30="","",CHOOSE(WEEKDAY(B30,2),"Montag","Dienstag","Mittwoch","Donnerstag","Freitag","Samstag","Sonntag")) -> Donnerstag | D30: 0.625 | E30: Leon Pachonik | F30: BÜW | G30: +49152333533366 | H30: 3507 | I30: Eltville | K30: 42.25 | M30: zwei Kabel gefunden | N30: 46241 | O30: 0.4375 | P30: Seebold | S30: Kabel geschnitten durch ALV | T30: Erledigt | U30: Ja
A31: 22 | B31: 46241 | C31: =IF(B31="","",CHOOSE(WEEKDAY(B31,2),"Montag","Dienstag","Mittwoch","Donnerstag","Freitag","Samstag","Sonntag")) -> Freitag | D31: 0.45833333 | E31: Leon Pachonik | F31: BÜW | G31: +49152333533366 | H31: 3507 | I31: Eltville | K31: 42.45 | M31: Ein kabel gefunden und gefenstert TK-Kabel papier | O31: 0.47222222 | P31: Seebold | S31: Kabel prov. Geschlossen
A32: 23 | B32: 46241 | C32: =IF(B32="","",CHOOSE(WEEKDAY(B32,2),"Montag","Dienstag","Mittwoch","Donnerstag","Freitag","Samstag","Sonntag")) -> Freitag | D32: 0.50972222 | E32: Leon Pachonik | F32: BÜW | G32: +49152333533366 | H32: 3507 | I32: Hattenheim | J32: Mast53/35 | N32: 46243 | O32: 0.38888889 | P32: Woodfin
A33: 24 | B33: 46242 | C33: =IF(B33="","",CHOOSE(WEEKDAY(B33,2),"Montag","Dienstag","Mittwoch","Donnerstag","Freitag","Samstag","Sonntag")) -> Samstag | D33: 0.34444444 | E33: Philipp Langer | F33: örtl. LST | G33: 015115544100 | H33: 3507 | I33: Niederwalluf | K33: 45.1 | M33: vsl. alte Kabel im Weg bei PSS Einbau | O33: 0.34583333 | P33: Woodfin | S33: Fenster in 5 Kabel geschnitten, Prov geschlossen, Klärungsbedarf 50Hz, TK | T33: in Klärung
A34: 25 | B34: 46244 | C34: =IF(B34="","",CHOOSE(WEEKDAY(B34,2),"Montag","Dienstag","Mittwoch","Donnerstag","Freitag","Samstag","Sonntag")) -> Montag | D34: 0.44722222 | E34: Leon Pachonik | F34: BÜW | G34: +49152333533366 | H34: 3507 | I34: Schierstein | J34: bei Mast 42/13 | M34: Kabelschaden
A35: 26 | B35: 46244 | C35: =IF(B35="","",CHOOSE(WEEKDAY(B35,2),"Montag","Dienstag","Mittwoch","Donnerstag","Freitag","Samstag","Sonntag")) -> Montag | D35: 0.50208333 | E35: Leon Pachonik | F35: BÜW | G35: +49152333533366 | H35: 3507 | I35: Hattenheim | J35: Gl.1 | M35: Kabelschaden bei Mast 54/0
C36: =IF(B36="","",CHOOSE(WEEKDAY(B36,2),"Montag","Dienstag","Mittwoch","Donnerstag","Freitag","Samstag","Sonntag")) | F36: =IF($E36="","",IFERROR(INDEX(Ansprechpartner!$F$4:$F$80,MATCH($E36,AP_Namen,0)),"")) | G36: =IF($E36="","",IFERROR(INDEX(Ansprechpartner!$C$4:$C$80,MATCH($E36,AP_Namen,0)),""))
C37: =IF(B37="","",CHOOSE(WEEKDAY(B37,2),"Montag","Dienstag","Mittwoch","Donnerstag","Freitag","Samstag","Sonntag")) | F37: =IF($E37="","",IFERROR(INDEX(Ansprechpartner!$F$4:$F$80,MATCH($E37,AP_Namen,0)),"")) | G37: =IF($E37="","",IFERROR(INDEX(Ansprechpartner!$C$4:$C$80,MATCH($E37,AP_Namen,0)),""))
C38: =IF(B38="","",CHOOSE(WEEKDAY(B38,2),"Montag","Dienstag","Mittwoch","Donnerstag","Freitag","Samstag","Sonntag")) | F38: =IF($E38="","",IFERROR(INDEX(Ansprechpartner!$F$4:$F$80,MATCH($E38,AP_Namen,0)),"")) | G38: =IF($E38="","",IFERROR(INDEX(Ansprechpartner!$C$4:$C$80,MATCH($E38,AP_Namen,0)),""))
C39: =IF(B39="","",CHOOSE(WEEKDAY(B39,2),"Montag","Dienstag","Mittwoch","Donnerstag","Freitag","Samstag","Sonntag")) | F39: =IF($E39="","",IFERROR(INDEX(Ansprechpartner!$F$4:$F$80,MATCH($E39,AP_Namen,0)),"")) | G39: =IF($E39="","",IFERROR(INDEX(Ansprechpartner!$C$4:$C$80,MATCH($E39,AP_Namen,0)),""))
C40: =IF(B40="","",CHOOSE(WEEKDAY(B40,2),"Montag","Dienstag","Mittwoch","Donnerstag","Freitag","Samstag","Sonntag")) | F40: =IF($E40="","",IFERROR(INDEX(Ansprechpartner!$F$4:$F$80,MATCH($E40,AP_Namen,0)),"")) | G40: =IF($E40="","",IFERROR(INDEX(Ansprechpartner!$C$4:$C$80,MATCH($E40,AP_Namen,0)),""))
...

Sheet BA2
A1: Kabelbereitschaft – Bauabschnitt 2
A2: Erledigt = „Ja“ → Zeile grün | In Klärung = „✔“ → Zeile gelb | Tag, Funktion, Telefonnummer automatisch | „Anzahl Kabel“ > 1 eintragen und Skript „Kabel-Unterzeilen erzeugen“ (Register Automatisieren) ausführen → Unterzeilen a/b/c werden eingefügt und auf-/zuklappbar gruppiert | Streckenkilometer ist Pflichtfeld | Blaue Einträge = aus Postfach
A3: Meldung | N3: Bearbeitung
A4: Lfd. Nr. | B4: Datum | C4: Tag | D4: Uhrzeit | E4: Anrufender | F4: Funktion des Anrufenden | G4: Telefonnummer | H4: Streckennummer | I4: Ortschaft | J4: Anlage (optional) | K4: Streckenkilometer | L4: Anzahl Kabel | M4: Meldung | N4: Annahme Datum | O4: Annahme Uhrzeit | P4: Mitarbeiter | Q4: Gewerk | R4: Kabeltyp | S4: Sachstand | T4: Notwendige Maßnahmen | U4: Erledigt (Ja/Nein) | V4: In Klärung (✔)
A5: 1 | B5: 46219 | C5: =IF(B5="","",CHOOSE(WEEKDAY(B5,2),"Montag","Dienstag","Mittwoch","Donnerstag","Freitag","Samstag","Sonntag")) -> Donnerstag | D5: 0.78263889 | E5: Nasser | F5: BÜW | G5: 0163/7837970 | H5: 3507 | I5: Grembach | J5: EÜ | K5: 120.972 | M5: 50_Hz Kabel, Email Meldung 19:03 | N5: 46220 | P5: Jürgen | S5: Stelle nicht gefunden
A6: 2 | B6: 46220 | C6: =IF(B6="","",CHOOSE(WEEKDAY(B6,2),"Montag","Dienstag","Mittwoch","Donnerstag","Freitag","Samstag","Sonntag")) -> Freitag | E6: Kleinwaechter | F6: LBÜW | G6: 15560701049 | H6: 2324 | K6: 89.3-102 | M6: diverese Kabel beschädigt die rausgerissen wurden | N6: 46222 | P6: Jürgen | S6: Diverse Kabel instandgesetzt
A7: 3 | B7: 46223 | C7: =IF(B7="","",CHOOSE(WEEKDAY(B7,2),"Montag","Dienstag","Mittwoch","Donnerstag","Freitag","Samstag","Sonntag")) -> Montag | D7: 0.52638889 | E7: Nasser | F7: BÜW | G7: 0163/7837970 | H7: 3507 | I7: Grembach | J7: EÜ | K7: 120.972 | M7: erenute Anfrage, 50_Hz Kabel, Email Meldung 19:03 | N7: 46223 | P7: Igor | S7: Stelle gefunden. Grube zu
A8: 4 | B8: 46224 | C8: =IF(B8="","",CHOOSE(WEEKDAY(B8,2),"Montag","Dienstag","Mittwoch","Donnerstag","Freitag","Samstag","Sonntag")) -> Dienstag | E8: Klewitz | F8: BÜW | G8: 0176/84839477 | H8: 3507 | I8: Oberlahnstein | J8: Bahnsteig | M8: Diverse Kabel
A9: 5 | B9: 46225 | C9: =IF(B9="","",CHOOSE(WEEKDAY(B9,2),"Montag","Dienstag","Mittwoch","Donnerstag","Freitag","Samstag","Sonntag")) -> Mittwoch | D9: 0.33333333 | E9: Akbabah | F9: BÜZ | G9: =IF($E9="","",IFERROR(INDEX(Ansprechpartner!$C$4:$C$80,MATCH($E9,AP_Namen,0)),"")) -> 0 | H9: 2324 | M9: Diverse Kabel
A10: 6 | B10: 46226 | C10: =IF(B10="","",CHOOSE(WEEKDAY(B10,2),"Montag","Dienstag","Mittwoch","Donnerstag","Freitag","Samstag","Sonntag")) -> Donnerstag | D10: 0.34652778 | E10: Sherzad | F10: BÜW | G10: 015116361122 | H10: 2324 | K10: 118 | M10: Diverse Kabel zur Identifikation | N10: 46226 | P10: Klewitz | S10: Kabel identifziert
A11: 7 | B11: 46238 | C11: =IF(B11="","",CHOOSE(WEEKDAY(B11,2),"Montag","Dienstag","Mittwoch","Donnerstag","Freitag","Samstag","Sonntag")) -> Dienstag | D11: 0.44027778 | E11: Klewitz | F11: BÜW-Kabel | G11: +49 17684839477 | H11: 3507 | I11: Oberlahnstein | K11: 121 | M11: Diverse Kabel identifizieren | N11: 46238 | O11: 0.44444444 | P11: Igor | S11: Kabel gefenstert und wieder Verschlossen
A12: 8 | B12: 46225 | C12: =IF(B12="","",CHOOSE(WEEKDAY(B12,2),"Montag","Dienstag","Mittwoch","Donnerstag","Freitag","Samstag","Sonntag")) -> Mittwoch | D12: 0.59652778 | E12: Klewitz | F12: BÜW-Kabel | G12: +49 17684839477 | I12: Oberlahnstein | K12: 122.5 | M12: Kabelfund, Zustimmung zum Schneiden angefragt (Schneideprotokoll an alle ALV: LST, TK, OLA, 50Hz). Protokoll: unbekannte Kabel, erdverlegt r.d.B. | S12: Zustimmungen liegen vor: W&S 22.07., LST (Baulig) 23.07., OLA (Jakobs) 23.07.
A13: 9 | B13: 46226 | C13: =IF(B13="","",CHOOSE(WEEKDAY(B13,2),"Montag","Dienstag","Mittwoch","Donnerstag","Freitag","Samstag","Sonntag")) -> Donnerstag | D13: 0.43402778 | E13: Klewitz | F13: BÜW-Kabel | G13: +49 17684839477 | I13: St. Goarshausen | K13: 94.1 | M13: Kabelfund, Zustimmung zum Schneiden angefragt (Schneideprotokoll an alle ALV: LST, TK, OLA, 50Hz). Protokoll: unbekanntes Kabel, l.d.B. hinter dem Bahnsteig. | S13: OLA (Jakobs) unterschrieben 27.07.
A14: 10 | B14: 46226 | C14: =IF(B14="","",CHOOSE(WEEKDAY(B14,2),"Montag","Dienstag","Mittwoch","Donnerstag","Freitag","Samstag","Sonntag")) -> Donnerstag | D14: 0.44513889 | E14: Klewitz | F14: BÜW-Kabel | G14: +49 17684839477 | I14: Oberlahnstein | K14: 122.3 | M14: Kabelfund, Zustimmung zum Schneiden angefragt (Schneideprotokoll an alle ALV: LST, TK, OLA, 50Hz). Protokoll: unbekanntes Kabel, l.d.B. | S14: OLA 27.07.: 2x OSE-Steuerkabel Mastschalter 3+4 betroffen, Kabeltrassen sichern und aus dem Baufeld verlegen
A15: 11 | B15: 46226 | C15: =IF(B15="","",CHOOSE(WEEKDAY(B15,2),"Montag","Dienstag","Mittwoch","Donnerstag","Freitag","Samstag","Sonntag")) -> Donnerstag | D15: 0.55833333 | E15: Klewitz | F15: BÜW-Kabel | G15: +49 17684839477 | I15: Kestert | K15: 100.9 | M15: Kabelfund, Zustimmung zum Schneiden angefragt (Schneideprotokoll an alle ALV: LST, TK, OLA, 50Hz). Protokoll: unbekannte Kabel im Schacht l.d.B., queren in den Schacht zwischen den Gleisen; LWL quert bis zum Schacht im Bahnsteig r.d.B. | S15: OLA 27.07.: möglicherweise Kabel zur OSE-Unterstation betroffen
A16: 12 | B16: 46227 | C16: =IF(B16="","",CHOOSE(WEEKDAY(B16,2),"Montag","Dienstag","Mittwoch","Donnerstag","Freitag","Samstag","Sonntag")) -> Freitag | D16: 0.45208333 | E16: Klewitz | F16: BÜW-Kabel | G16: +49 17684839477 | I16: Oberlahnstein | K16: 121 | M16: Kabelfund, Zustimmung zum Schneiden angefragt (Schneideprotokoll an alle ALV: LST, TK, OLA, 50Hz). Protokoll: unbekanntes Kabel, r.d.B. | S16: OLA 27.07.: 4x OSE-Steuerkabel Mastschalter 3, 4, 5 + Wandler, 8, 401, 402, 508 betroffen; Trassen sichern und verlegen
A17: 13 | B17: 46227 | C17: =IF(B17="","",CHOOSE(WEEKDAY(B17,2),"Montag","Dienstag","Mittwoch","Donnerstag","Freitag","Samstag","Sonntag")) -> Freitag | D17: 0.45555556 | E17: Klewitz | F17: BÜW-Kabel | G17: +49 17684839477 | I17: Oberlahnstein | K17: 121.4 | M17: Kabelfund, Zustimmung zum Schneiden angefragt (Schneideprotokoll an alle ALV: LST, TK, OLA, 50Hz). Protokoll: unbekanntes Kabel, l.d.B. | S17: OLA (Jakobs) unterschrieben 27.07.
A18: 14 | B18: 46227 | C18: =IF(B18="","",CHOOSE(WEEKDAY(B18,2),"Montag","Dienstag","Mittwoch","Donnerstag","Freitag","Samstag","Sonntag")) -> Freitag | D18: 0.45763889 | E18: Klewitz | F18: BÜW-Kabel | G18: +49 17684839477 | I18: Oberlahnstein | K18: 122 | M18: Kabelfund, Zustimmung zum Schneiden angefragt (Schneideprotokoll an alle ALV: LST, TK, OLA, 50Hz). Protokoll: unbekanntes Kabel, l.d.B. | S18: OLA 28.07.: 2x OSE-Steuerkabel Mastschalter 3+4 betroffen; Trassen sichern und verlegen
A19: 15 | B19: 46228 | C19: =IF(B19="","",CHOOSE(WEEKDAY(B19,2),"Montag","Dienstag","Mittwoch","Donnerstag","Freitag","Samstag","Sonntag")) -> Samstag | D19: 0.45555556 | E19: Klewitz, Christian | F19: BÜW-Kabel | G19: +49 17684839477 | I19: Oberlahnstein | K19: 121.4 | M19: Kabelfund rechts neben der Bahn Prüfen | S19: Kabel gefenstert und wieder Verschlossen TK Kabel
A20: 16 | B20: 46228 | C20: =IF(B20="","",CHOOSE(WEEKDAY(B20,2),"Montag","Dienstag","Mittwoch","Donnerstag","Freitag","Samstag","Sonntag")) -> Samstag | D20: 0.45763889 | E20: Klewitz | F20: BÜW-Kabel | G20: +49 17684839477 | I20: Oberlahnstein | K20: 122.5 | M20: Kabelfund Prüfen | S20: Kabel gefenstert und wieder Verschlossen LST Kabel
A21: 17 | B21: 46230 | C21: =IF(B21="","",CHOOSE(WEEKDAY(B21,2),"Montag","Dienstag","Mittwoch","Donnerstag","Freitag","Samstag","Sonntag")) -> Montag | D21: 0.45763889 | E21: Klewitz | F21: BÜW-Kabel | G21: +49 17684839477 | I21: Oberlahnstein | K21: 121.85 | M21: Kabelfund Prüfen | S21: Kabel gefenstert und wieder Verschlossen 50 Kabel
A22: 18 | B22: 46231 | C22: =IF(B22="","",CHOOSE(WEEKDAY(B22,2),"Montag","Dienstag","Mittwoch","Donnerstag","Freitag","Samstag","Sonntag")) -> Dienstag | D22: 0.34652778 | E22: Klewitz | F22: BÜW-Kabel | G22: +49 17684839477 | I22: Grenbach | J22: EÜ | K22: 120.9 | M22: 5 Kabelfunde EÜ Grenbach, alle r.d.B. – 5 Schneideprotokolle: EZ OSE 020-1 (NYY-O 10x2,5), EZ OSE 010 (NYY-O 10x2,5), EZ OSE 020-2 (NYY-O 10x2,5), EZ OSE 050 (NYY-O 14x2,5), ESTW-W3 (ST 6x2x0,6). Zustimmung zum Schneiden angefragt. | S22: OLA 05.08.: OSE-Steuerkabel Masttrennschalter + Steuerkabel WHZ W3 betroffen; Trassen sichern und verlegen
A23: 19 | B23: 46232 | C23: =IF(B23="","",CHOOSE(WEEKDAY(B23,2),"Montag","Dienstag","Mittwoch","Donnerstag","Freitag","Samstag","Sonntag")) -> Mittwoch | D23: 0.34513889 | E23: Klewitz | F23: BÜW-Kabel | G23: +49 17684839477 | I23: Filsen | K23: 109.2 | M23: Kabelfund, Zustimmung zum Schneiden angefragt (Schneideprotokoll an alle ALV: LST, TK, OLA, 50Hz). Protokoll: unbekanntes Kabel, r.d.B. (VST Filsen Gleis 1, Bergseite). | S23: OLA (Jakobs) unterschrieben 05.08.
A24: 20 | B24: 46233 | C24: =IF(B24="","",CHOOSE(WEEKDAY(B24,2),"Montag","Dienstag","Mittwoch","Donnerstag","Freitag","Samstag","Sonntag")) -> Donnerstag | D24: 0.44722222 | E24: Klewitz | F24: BÜW-Kabel | G24: +49 17684839477 | I24: Kamp-Bornhofen | K24: 106.1 | M24: Kabelfund, Zustimmung zum Schneiden angefragt (Schneideprotokoll an alle ALV: LST, TK, OLA, 50Hz). Protokoll: unbekanntes Kabel, r.d.B. | S24: OFFEN – Erinnerung Klewitz 10.08.: Rückmeldung Stegemann/Fromm/Jakobs fehlt noch, bislang nur LST | V24: ✔
A25: 21 | B25: 46233 | C25: =IF(B25="","",CHOOSE(WEEKDAY(B25,2),"Montag","Dienstag","Mittwoch","Donnerstag","Freitag","Samstag","Sonntag")) -> Donnerstag | D25: 0.58055556 | E25: Klewitz | F25: BÜW-Kabel | G25: +49 17684839477 | I25: Filsen | K25: 109.2 | M25: Erneuter Kabelfund (lt. Protokoll km 109,12), Zustimmung zum Schneiden angefragt. Protokoll: unbekanntes Kabel. | S25: 05.08.: zusätzliches Fenster geschnitten, Rückmeldung dringend angefragt
A26: 22 | B26: 46234 | C26: =IF(B26="","",CHOOSE(WEEKDAY(B26,2),"Montag","Dienstag","Mittwoch","Donnerstag","Freitag","Samstag","Sonntag")) -> Freitag | D26: 0.34444444 | E26: Klewitz | F26: BÜW-Kabel | G26: +49 17684839477 | I26: Braubach | K26: 116.6 | M26: Kabelfund, Zustimmung zum Schneiden angefragt (Schneideprotokoll an alle ALV: LST, TK, OLA, 50Hz). Protokoll: unbekanntes Kabel, l.d.B.
A27: 23 | B27: 46234 | C27: =IF(B27="","",CHOOSE(WEEKDAY(B27,2),"Montag","Dienstag","Mittwoch","Donnerstag","Freitag","Samstag","Sonntag")) -> Freitag | D27: 0.34513889 | E27: Klewitz | F27: BÜW-Kabel | G27: +49 17684839477 | I27: Braubach | K27: 116.7 | M27: Kabelfund, Zustimmung zum Schneiden angefragt (Schneideprotokoll an alle ALV: LST, TK, OLA, 50Hz). Protokoll: unbekanntes Kabel, l.d.B.
A28: 24 | B28: 46234 | C28: =IF(B28="","",CHOOSE(WEEKDAY(B28,2),"Montag","Dienstag","Mittwoch","Donnerstag","Freitag","Samstag","Sonntag")) -> Freitag | D28: 0.35138889 | E28: Klewitz | F28: BÜW-Kabel | G28: +49 17684839477 | I28: Kamp-Bornhofen | K28: 108.834 | M28: Kabelfund, Zustimmung zum Schneiden angefragt (Schneideprotokoll an alle ALV: LST, TK, OLA, 50Hz). Protokoll: unbekanntes Kabel, l.d.B. hinter der Brücke.
A29: 25 | B29: 46240 | C29: =IF(B29="","",CHOOSE(WEEKDAY(B29,2),"Montag","Dienstag","Mittwoch","Donnerstag","Freitag","Samstag","Sonntag")) -> Donnerstag | D29: 0.39861111 | E29: Klewitz | F29: BÜW-Kabel | G29: +49 17684839477 | I29: Oberlahnstein | K29: 121.351 | M29: Unbekannte Kabel gefunden, Mithilfe zur Identifikation angefragt. 2 Protokolle: TK-Kabel 700 (27x1,4) sowie unbekanntes Kabel, beide l.d.B. im Kabelschacht.
F30: =IF($E30="","",IFERROR(INDEX(Ansprechpartner!$F$4:$F$80,MATCH($E30,AP_Namen,0)),"")) | G30: =IF($E30="","",IFERROR(INDEX(Ansprechpartner!$C$4:$C$80,MATCH($E30,AP_Namen,0)),""))
F31: =IF($E31="","",IFERROR(INDEX(Ansprechpartner!$F$4:$F$80,MATCH($E31,AP_Namen,0)),"")) | G31: =IF($E31="","",IFERROR(INDEX(Ansprechpartner!$C$4:$C$80,MATCH($E31,AP_Namen,0)),""))
F32: =IF($E32="","",IFERROR(INDEX(Ansprechpartner!$F$4:$F$80,MATCH($E32,AP_Namen,0)),"")) | G32: =IF($E32="","",IFERROR(INDEX(Ansprechpartner!$C$4:$C$80,MATCH($E32,AP_Namen,0)),""))
F33: =IF($E33="","",IFERROR(INDEX(Ansprechpartner!$F$4:$F$80,MATCH($E33,AP_Namen,0)),"")) | G33: =IF($E33="","",IFERROR(INDEX(Ansprechpartner!$C$4:$C$80,MATCH($E33,AP_Namen,0)),""))
F34: =IF($E34="","",IFERROR(INDEX(Ansprechpartner!$F$4:$F$80,MATCH($E34,AP_Namen,0)),"")) | G34: =IF($E34="","",IFERROR(INDEX(Ansprechpartner!$C$4:$C$80,MATCH($E34,AP_Namen,0)),""))
F35: =IF($E35="","",IFERROR(INDEX(Ansprechpartner!$F$4:$F$80,MATCH($E35,AP_Namen,0)),"")) | G35: =IF($E35="","",IFERROR(INDEX(Ansprechpartner!$C$4:$C$80,MATCH($E35,AP_Namen,0)),""))
C36: =IF(B36="","",CHOOSE(WEEKDAY(B36,2),"Montag","Dienstag","Mittwoch","Donnerstag","Freitag","Samstag","Sonntag")) | F36: =IF($E36="","",IFERROR(INDEX(Ansprechpartner!$F$4:$F$80,MATCH($E36,AP_Namen,0)),"")) | G36: =IF($E36="","",IFERROR(INDEX(Ansprechpartner!$C$4:$C$80,MATCH($E36,AP_Namen,0)),""))
C37: =IF(B37="","",CHOOSE(WEEKDAY(B37,2),"Montag","Dienstag","Mittwoch","Donnerstag","Freitag","Samstag","Sonntag")) | F37: =IF($E37="","",IFERROR(INDEX(Ansprechpartner!$F$4:$F$80,MATCH($E37,AP_Namen,0)),"")) | G37: =IF($E37="","",IFERROR(INDEX(Ansprechpartner!$C$4:$C$80,MATCH($E37,AP_Namen,0)),""))
C38: =IF(B38="","",CHOOSE(WEEKDAY(B38,2),"Montag","Dienstag","Mittwoch","Donnerstag","Freitag","Samstag","Sonntag")) | F38: =IF($E38="","",IFERROR(INDEX(Ansprechpartner!$F$4:$F$80,MATCH($E38,AP_Namen,0)),"")) | G38: =IF($E38="","",IFERROR(INDEX(Ansprechpartner!$C$4:$C$80,MATCH($E38,AP_Namen,0)),""))
C39: =IF(B39="","",CHOOSE(WEEKDAY(B39,2),"Montag","Dienstag","Mittwoch","Donnerstag","Freitag","Samstag","Sonntag")) | F39: =IF($E39="","",IFERROR(INDEX(Ansprechpartner!$F$4:$F$80,MATCH($E39,AP_Namen,0)),"")) | G39: =IF($E39="","",IFERROR(INDEX(Ansprechpartner!$C$4:$C$80,MATCH($E39,AP_Namen,0)),""))
C40: =IF(B40="","",CHOOSE(WEEKDAY(B40,2),"Montag","Dienstag","Mittwoch","Donnerstag","Freitag","Samstag","Sonntag")) | F40: =IF($E40="","",IFERROR(INDEX(Ansprechpartner!$F$4:$F$80,MATCH($E40,AP_Namen,0)),"")) | G40: =IF($E40="","",IFERROR(INDEX(Ansprechpartner!$C$4:$C$80,MATCH($E40,AP_Namen,0)),""))
...

Sheet BA3
A1: Kabelbereitschaft – Bauabschnitt 3
A2: Erledigt = „Ja“ → Zeile grün | In Klärung = „✔“ → Zeile gelb | Tag, Funktion, Telefonnummer automatisch | „Anzahl Kabel“ > 1 eintragen und Skript „Kabel-Unterzeilen erzeugen“ (Register Automatisieren) ausführen → Unterzeilen a/b/c werden eingefügt und auf-/zuklappbar gruppiert | Streckenkilometer ist Pflichtfeld | Blaue Einträge = aus Postfach
A3: Meldung | N3: Bearbeitung
A4: Lfd. Nr. | B4: Datum | C4: Tag | D4: Uhrzeit | E4: Anrufender | F4: Funktion des Anrufenden | G4: Telefonnummer | H4: Streckennummer | I4: Ortschaft | J4: Anlage (optional) | K4: Streckenkilometer | L4: Anzahl Kabel | M4: Meldung | N4: Annahme Datum | O4: Annahme Uhrzeit | P4: Mitarbeiter | Q4: Gewerk | R4: Kabeltyp | S4: Sachstand | T4: Notwendige Maßnahmen | U4: Erledigt (Ja/Nein) | V4: In Klärung (✔)
A5: 1 | B5: 46223 | C5: =IF(B5="","",CHOOSE(WEEKDAY(B5,2),"Montag","Dienstag","Mittwoch","Donnerstag","Freitag","Samstag","Sonntag")) -> Montag | D5: 0.75 | E5: Baulich | F5: ALV | G5: =IF($E5="","",IFERROR(INDEX(Ansprechpartner!$C$4:$C$80,MATCH($E5,AP_Namen,0)),"")) | I5: Niederlahnsteine | J5: W2 | M5: A20x1x0,9 | N5: 46224 | O5: 0.475 | P5: J_ Meier | S5: erldigt. Kabel aufgelegt | U5: Ja
A6: 2 | B6: 46224 | C6: =IF(B6="","",CHOOSE(WEEKDAY(B6,2),"Montag","Dienstag","Mittwoch","Donnerstag","Freitag","Samstag","Sonntag")) -> Dienstag | D6: 0.59583333 | F6: BÜW | G6: =IF($E6="","",IFERROR(INDEX(Ansprechpartner!$C$4:$C$80,MATCH($E6,AP_Namen,0)),"")) | I6: Niederlahnsteine | J6: Gl. 4-5 | M6: Kabel beschädigt durch LW, FDL hat Störung | N6: 46224 | O6: 0.75 | P6: J_ Meier | S6: 3adriges Kabel alt | U6: Ja
A7: 3 | B7: 46225 | C7: =IF(B7="","",CHOOSE(WEEKDAY(B7,2),"Montag","Dienstag","Mittwoch","Donnerstag","Freitag","Samstag","Sonntag")) -> Mittwoch | D7: 0.72569444 | F7: BÜW | G7: 015123297056 | H7: 3011 | I7: Lahn | J7: Strecke | K7: 7.4 | M7: 3 Kabel beschädigt. Auswirkung FDL. Befehl | N7: 46226 | O7: 0.55555556 | P7: Igor M | S7: 1x Schutzmuffe 1x Verbindungsmuffe 20er, 1TK | U7: Ja
A8: 4 | B8: 46227 | C8: =IF(B8="","",CHOOSE(WEEKDAY(B8,2),"Montag","Dienstag","Mittwoch","Donnerstag","Freitag","Samstag","Sonntag")) -> Freitag | D8: 0.82291667 | E8: UZUM | F8: BÜW | G8: +4915112259736 | H8: 3507 | I8: Niederlahnsteine | J8: W2 | K8: 123.3 | M8: Ein kabel ist im Weg zur erstellung der PSS | N8: 46227 | O8: 0.94305556 | P8: Igor M | S8: Geschnitten altes Kabel | T8: Protokoll Fehlt mündliche zustimmung Baulig
A9: 5 | B9: 46230 | C9: =IF(B9="","",CHOOSE(WEEKDAY(B9,2),"Montag","Dienstag","Mittwoch","Donnerstag","Freitag","Samstag","Sonntag")) -> Montag | D9: 0.44930556 | E9: Klappert | F9: BÜW | G9: +4915112259778 | H9: 3710 | I9: Niederlahnsteine | J9: Sia6 | K9: 100.445 | M9: Kabel im Weg für Fundament Sigausleger | N9: 46230 | O9: 0.48055556 | P9: Igor M | S9: 10 Kabel gefenstert und geschnitten nach Rücksprache Klewenz | T9: Kabel geschnitten | U9: Ja
A10: 6 | B10: 46231 | C10: =IF(B10="","",CHOOSE(WEEKDAY(B10,2),"Montag","Dienstag","Mittwoch","Donnerstag","Freitag","Samstag","Sonntag")) -> Dienstag | D10: 0.3125 | E10: Theo | F10: BÜW LSW | G10: +4915233305508 | H10: 2324 | I10: Bendorf | J10: LSW | K10: 143.54 | M10: Kabel beschädigt durch LW | N10: 46231 | P10: Retzlaw | V10: ✔
A11: 7 | B11: 46238 | C11: =IF(B11="","",CHOOSE(WEEKDAY(B11,2),"Montag","Dienstag","Mittwoch","Donnerstag","Freitag","Samstag","Sonntag")) -> Dienstag | D11: 0.39583333 | E11: BZL RR BA3 | F11: BÜW | G11: +4915123297056 | H11: 2324 | I11: Neuwied | J11: KNE | K11: 136.217 | M11: Kabelschaden zw. Gl 013 und Gl 064 3m hinter R64 | N11: 46238 | O11: 0.43333333 | P11: Stempel | S11: Altkabel keine ausfälle im STW geschnitten 2x | U11: Ja
A12: 8 | B12: 46238 | C12: =IF(B12="","",CHOOSE(WEEKDAY(B12,2),"Montag","Dienstag","Mittwoch","Donnerstag","Freitag","Samstag","Sonntag")) -> Dienstag | D12: 0.39722222 | E12: Aslihan Cüccam | F12: BÜW OB | G12: +4915112259723 | H12: 2324 | I12: Neuwied | J12: DKW 56 | K12: km 136,250 | M12: Energiekabel gerissen 4*10² | N12: 46238 | O12: 0.60555556 | P12: Stempel | S12: Kabel gemufft 6m eingespleist | U12: Ja
A13: 9 | B13: 46238 | C13: =IF(B13="","",CHOOSE(WEEKDAY(B13,2),"Montag","Dienstag","Mittwoch","Donnerstag","Freitag","Samstag","Sonntag")) -> Dienstag | D13: 0.40277778 | E13: BZL RR BA3 | F13: BÜW | G13: +4915123297056 | H13: 2324 | I13: Neuwied | J13: EW 64 | K13: km 136,2 | M13: Erdung und Weichheizungsverteiler def. | N13: 46238 | O13: 0.48125 | P13: Stempel | S13: Verteiler und Erdung muss erneuert werden durch AN Bau | U13: Ja
A14: 10 | B14: 46238 | C14: =IF(B14="","",CHOOSE(WEEKDAY(B14,2),"Montag","Dienstag","Mittwoch","Donnerstag","Freitag","Samstag","Sonntag")) -> Dienstag | D14: 0.45833333 | E14: BZL RR BA3 | F14: BÜW | G14: +4915123297056 | H14: 2324 | I14: Neuwied | K14: km 137,0 | M14: Kabel bei Rahmrohrgründung gefunden | N14: 46238 | O14: 0.49444444 | P14: Stempel | S14: Altkabel keine ausfälle im STW geschnitten 2x Stofisoliert | U14: Ja
A15: 11 | B15: 46238 | C15: =IF(B15="","",CHOOSE(WEEKDAY(B15,2),"Montag","Dienstag","Mittwoch","Donnerstag","Freitag","Samstag","Sonntag")) -> Dienstag | D15: 0.79444444 | E15: BZL RR BA3 | F15: BÜW | G15: +4915123297056 | H15: 2324 | I15: KO-ehrenbreitstein | K15: 151.3 | M15: Rohrtrasse gefunden mit Kabeln | N15: 46239 | O15: 0.43819444 | P15: Stempel | S15: Kabeltrasse beim Eintreffen geschnitten, anordnung durch BÜW Norman Schacher Tel: 01733915685 Baufeldfreimachung im vorfeld erfolgt | U15: Ja
A16: 12 | B16: 46239 | C16: =IF(B16="","",CHOOSE(WEEKDAY(B16,2),"Montag","Dienstag","Mittwoch","Donnerstag","Freitag","Samstag","Sonntag")) -> Mittwoch | D16: 0.25972222 | E16: BZL RR BA3 | F16: BÜW | G16: +4915123297056 | H16: 2324 | I16: Neuwied | J16: W27 | M16: Kabel provesorisch repariert bitte ordentlich Reparieren | N16: 46239 | O16: 0.53611111 | P16: stempel | S16: Kabel ordnungsgemäß gemufft | U16: Ja
A17: 13 | B17: 46241 | C17: =IF(B17="","",CHOOSE(WEEKDAY(B17,2),"Montag","Dienstag","Mittwoch","Donnerstag","Freitag","Samstag","Sonntag")) -> Freitag | D17: 0.25 | E17: BZL RR BA3 | F17: BÜW | G17: +4915123297056 | H17: 2324 | I17: Neuwied | J17: W45 | M17: Weiche wurde aufgefahren | N17: 46241 | O17: 0.39583333 | P17: 46241 | S17: Weiche wird überprüft freigabe von BÜW OD befahrbar | U17: Ja
A18: 14 | B18: 46241 | C18: =IF(B18="","",CHOOSE(WEEKDAY(B18,2),"Montag","Dienstag","Mittwoch","Donnerstag","Freitag","Samstag","Sonntag")) -> Freitag | D18: 0.61458333 | E18: BLZ BA3 Eckert | F18: BÜW | G18: +4915123297056 | H18: 2324 | I18: Neuwied | J18: Sia27 | K18: 136.713 | M18: Kabel im Weg für Fundament Signalausleger | N18: 46241 | O18: 0.71041667 | P18: Breuer | S18: 3 TK Kabel gefenstert, prov. Geschlossen | V18: ✔
A19: 15 | B19: 46241 | C19: =IF(B19="","",CHOOSE(WEEKDAY(B19,2),"Montag","Dienstag","Mittwoch","Donnerstag","Freitag","Samstag","Sonntag")) -> Freitag | D19: 0.72569444 | E19: BLZ BA3 | F19: BÜW | G19: +4915123297056 | H19: 3710 | I19: Niederlahnstein | J19: Gl.106 | M19: Bei Baggerarbeiten Kabel beschädigt | S19: Sipla in Klärung | V19: ✔
A20: 16 | B20: 46242 | C20: =IF(B20="","",CHOOSE(WEEKDAY(B20,2),"Montag","Dienstag","Mittwoch","Donnerstag","Freitag","Samstag","Sonntag")) -> Samstag | D20: 0.49166667 | E20: BLZ BA3 Graule | F20: =IF($E20="","",IFERROR(INDEX(Ansprechpartner!$F$4:$F$80,MATCH($E20,AP_Namen,0)),"")) | G20: +4915123297056 | H20: 2324 | I20: Niederlahnstein | J20: r.d.Bahn | K20: 153.916 | M20: Bagger, Kabel Beschädigung | N20: 46242 | P20: Becker | S20: SKV8/20 zestört, Kabel prov. eingeführt und aufgelegt | U20: Ja
A21: 17 | B21: 46242 | C21: =IF(B21="","",CHOOSE(WEEKDAY(B21,2),"Montag","Dienstag","Mittwoch","Donnerstag","Freitag","Samstag","Sonntag")) -> Samstag | E21: BLZ BA3 Kalchreuter | F21: =IF($E21="","",IFERROR(INDEX(Ansprechpartner!$F$4:$F$80,MATCH($E21,AP_Namen,0)),"")) | G21: +4915123297056 | H21: 3507 | I21: Niederlahnstein | J21: Gl.207 | K21: 125.497 | M21: Kabel bei Kabelkanal setzen beschädigt | N21: 46242 | O21: 0.73958333 | P21: Becker | S21: SKV8/20 zestört, beide Kabel bereits geschnitten, Kabel und 500Hz Magnet fehlen bereits | U21: Ja
A22: 18 | B22: 46242 | C22: =IF(B22="","",CHOOSE(WEEKDAY(B22,2),"Montag","Dienstag","Mittwoch","Donnerstag","Freitag","Samstag","Sonntag")) -> Samstag | E22: BLZ BA3 Kalchreuter | F22: =IF($E22="","",IFERROR(INDEX(Ansprechpartner!$F$4:$F$80,MATCH($E22,AP_Namen,0)),"")) | G22: +4915123297056 | H22: 3507 | I22: Niederlahnstein | J22: l.d.Bahn | K22: 125.4 | M22: Kabel bei Kabelkanal setzen beschädigt | N22: 46242 | O22: 0.75694444 | P22: Becker | S22: Schadstelle kann nicht gefunden werden, Schadstelle verfüllt | U22: Ja
A23: 19 | B23: 46244 | C23: =IF(B23="","",CHOOSE(WEEKDAY(B23,2),"Montag","Dienstag","Mittwoch","Donnerstag","Freitag","Samstag","Sonntag")) -> Montag | D23: 0.34166667 | E23: BLZ BA3 Gebel-Marloth | F23: =IF($E23="","",IFERROR(INDEX(Ansprechpartner!$F$4:$F$80,MATCH($E23,AP_Namen,0)),"")) | G23: +4915123297056 | H23: 2324 | I23: Neuwied | J23: Gl.8 | M23: bei Aushubarbeiten im Gl. 8 ein Kabel beschädigt | N23: 46244 | O23: 0.37708333 | P23: Igor M | S23: 50Hz Schutzmuffe montiert | U23: Ja
C24: =IF(B24="","",CHOOSE(WEEKDAY(B24,2),"Montag","Dienstag","Mittwoch","Donnerstag","Freitag","Samstag","Sonntag")) | F24: =IF($E24="","",IFERROR(INDEX(Ansprechpartner!$F$4:$F$80,MATCH($E24,AP_Namen,0)),"")) | G24: =IF($E24="","",IFERROR(INDEX(Ansprechpartner!$C$4:$C$80,MATCH($E24,AP_Namen,0)),""))
C25: =IF(B25="","",CHOOSE(WEEKDAY(B25,2),"Montag","Dienstag","Mittwoch","Donnerstag","Freitag","Samstag","Sonntag")) | F25: =IF($E25="","",IFERROR(INDEX(Ansprechpartner!$F$4:$F$80,MATCH($E25,AP_Namen,0)),"")) | G25: =IF($E25="","",IFERROR(INDEX(Ansprechpartner!$C$4:$C$80,MATCH($E25,AP_Namen,0)),""))
C26: =IF(B26="","",CHOOSE(WEEKDAY(B26,2),"Montag","Dienstag","Mittwoch","Donnerstag","Freitag","Samstag","Sonntag")) | F26: =IF($E26="","",IFERROR(INDEX(Ansprechpartner!$F$4:$F$80,MATCH($E26,AP_Namen,0)),"")) | G26: =IF($E26="","",IFERROR(INDEX(Ansprechpartner!$C$4:$C$80,MATCH($E26,AP_Namen,0)),""))
C27: =IF(B27="","",CHOOSE(WEEKDAY(B27,2),"Montag","Dienstag","Mittwoch","Donnerstag","Freitag","Samstag","Sonntag")) | F27: =IF($E27="","",IFERROR(INDEX(Ansprechpartner!$F$4:$F$80,MATCH($E27,AP_Namen,0)),"")) | G27: =IF($E27="","",IFERROR(INDEX(Ansprechpartner!$C$4:$C$80,MATCH($E27,AP_Namen,0)),""))
C28: =IF(B28="","",CHOOSE(WEEKDAY(B28,2),"Montag","Dienstag","Mittwoch","Donnerstag","Freitag","Samstag","Sonntag")) | F28: =IF($E28="","",IFERROR(INDEX(Ansprechpartner!$F$4:$F$80,MATCH($E28,AP_Namen,0)),"")) | G28: =IF($E28="","",IFERROR(INDEX(Ansprechpartner!$C$4:$C$80,MATCH($E28,AP_Namen,0)),""))
C29: =IF(B29="","",CHOOSE(WEEKDAY(B29,2),"Montag","Dienstag","Mittwoch","Donnerstag","Freitag","Samstag","Sonntag")) | F29: =IF($E29="","",IFERROR(INDEX(Ansprechpartner!$F$4:$F$80,MATCH($E29,AP_Namen,0)),"")) | G29: =IF($E29="","",IFERROR(INDEX(Ansprechpartner!$C$4:$C$80,MATCH($E29,AP_Namen,0)),""))
C30: =IF(B30="","",CHOOSE(WEEKDAY(B30,2),"Montag","Dienstag","Mittwoch","Donnerstag","Freitag","Samstag","Sonntag")) | F30: =IF($E30="","",IFERROR(INDEX(Ansprechpartner!$F$4:$F$80,MATCH($E30,AP_Namen,0)),"")) | G30: =IF($E30="","",IFERROR(INDEX(Ansprechpartner!$C$4:$C$80,MATCH($E30,AP_Namen,0)),""))
C31: =IF(B31="","",CHOOSE(WEEKDAY(B31,2),"Montag","Dienstag","Mittwoch","Donnerstag","Freitag","Samstag","Sonntag")) | F31: =IF($E31="","",IFERROR(INDEX(Ansprechpartner!$F$4:$F$80,MATCH($E31,AP_Namen,0)),"")) | G31: =IF($E31="","",IFERROR(INDEX(Ansprechpartner!$C$4:$C$80,MATCH($E31,AP_Namen,0)),""))
C32: =IF(B32="","",CHOOSE(WEEKDAY(B32,2),"Montag","Dienstag","Mittwoch","Donnerstag","Freitag","Samstag","Sonntag")) | F32: =IF($E32="","",IFERROR(INDEX(Ansprechpartner!$F$4:$F$80,MATCH($E32,AP_Namen,0)),"")) | G32: =IF($E32="","",IFERROR(INDEX(Ansprechpartner!$C$4:$C$80,MATCH($E32,AP_Namen,0)),""))
C33: =IF(B33="","",CHOOSE(WEEKDAY(B33,2),"Montag","Dienstag","Mittwoch","Donnerstag","Freitag","Samstag","Sonntag")) | F33: =IF($E33="","",IFERROR(INDEX(Ansprechpartner!$F$4:$F$80,MATCH($E33,AP_Namen,0)),"")) | G33: =IF($E33="","",IFERROR(INDEX(Ansprechpartner!$C$4:$C$80,MATCH($E33,AP_Namen,0)),""))
C34: =IF(B34="","",CHOOSE(WEEKDAY(B34,2),"Montag","Dienstag","Mittwoch","Donnerstag","Freitag","Samstag","Sonntag")) | F34: =IF($E34="","",IFERROR(INDEX(Ansprechpartner!$F$4:$F$80,MATCH($E34,AP_Namen,0)),"")) | G34: =IF($E34="","",IFERROR(INDEX(Ansprechpartner!$C$4:$C$80,MATCH($E34,AP_Namen,0)),""))
C35: =IF(B35="","",CHOOSE(WEEKDAY(B35,2),"Montag","Dienstag","Mittwoch","Donnerstag","Freitag","Samstag","Sonntag")) | F35: =IF($E35="","",IFERROR(INDEX(Ansprechpartner!$F$4:$F$80,MATCH($E35,AP_Namen,0)),"")) | G35: =IF($E35="","",IFERROR(INDEX(Ansprechpartner!$C$4:$C$80,MATCH($E35,AP_Namen,0)),""))
... C300: =IF(B300="","",CHOOSE(WEEKDAY(B300,2),"Montag","Dienstag","Mittwoch","Donnerstag","Freitag","Samstag","Sonntag")) | F300: =IF($E300="","",IFERROR(INDEX(Ansprechpartner!$F$4:$F$80,MATCH($E300,AP_Namen,0)),"")) | G300: =IF($E300="","",IFERROR(INDEX(Ansprechpartner!$C$4:$C$80,MATCH($E300,AP_Namen,0)),""))

Sheet Ansprechpartner
A1: Ansprechpartner
A2: Neue Ansprechpartner hier eintragen – sie erscheinen automatisch als Auswahl im Feld „Anrufender“ der BA-Blätter; Funktion und Telefonnummer werden dort automatisch übernommen. Freitext bleibt möglich.
A3: Name | B3: Vorname | C3: Telefonnummer | D3: BA | E3: Anzeigename (automatisch) | F3: Funktion
A4: Kräner | C4: 015750662038 | D4: BA 1 | E4: =IF($A4="","",TRIM($A4&IF($B4<>"",", "&$B4,""))) -> Kräner | F4: BÜW
A5: Esen | B5: Fadime | C5: 015758316071 | D5: BA 1 | E5: =IF($A5="","",TRIM($A5&IF($B5<>"",", "&$B5,""))) -> Esen, Fadime | F5: LBÜW
A6: Altinos | B6: Emre | C6: 015224173988 | D6: BA 1 | E6: =IF($A6="","",TRIM($A6&IF($B6<>"",", "&$B6,""))) -> Altinos, Emre | F6: BÜW
A7: Müller | C7: 0171/3309584 | D7: BA 1 | E7: =IF($A7="","",TRIM($A7&IF($B7<>"",", "&$B7,""))) -> Müller | F7: BÜW
A8: Pachonik | B8: Leon | C8: +49152333533366 | D8: BA 1 | E8: =IF($A8="","",TRIM($A8&IF($B8<>"",", "&$B8,""))) -> Pachonik, Leon | F8: BÜW
A9: Pernal | B9: Natan | C9: +4915233326507 | D9: BA 1 | E9: =IF($A9="","",TRIM($A9&IF($B9<>"",", "&$B9,""))) -> Pernal, Natan | F9: BÜW
A10: Langer | B10: Philipp | C10: 015115544100 | D10: BA 1 | E10: =IF($A10="","",TRIM($A10&IF($B10<>"",", "&$B10,""))) -> Langer, Philipp | F10: örtl. LST
A11: Nasser | C11: 0163/7837970 | D11: BA 2 | E11: =IF($A11="","",TRIM($A11&IF($B11<>"",", "&$B11,""))) -> Nasser | F11: BÜW
A12: Kleinwaechter | C12: 015560701049 | D12: BA 2 | E12: =IF($A12="","",TRIM($A12&IF($B12<>"",", "&$B12,""))) -> Kleinwaechter | F12: LBÜW
A13: Klewitz | B13: Christian | C13: +49 17684839477 | D13: BA 2 | E13: =IF($A13="","",TRIM($A13&IF($B13<>"",", "&$B13,""))) -> Klewitz, Christian | F13: BÜW-Kabel
A14: Akbabah | D14: BA 2 | E14: =IF($A14="","",TRIM($A14&IF($B14<>"",", "&$B14,""))) -> Akbabah | F14: BÜZ
A15: Sherzad | C15: 015116361122 | D15: BA 2 | E15: =IF($A15="","",TRIM($A15&IF($B15<>"",", "&$B15,""))) -> Sherzad | F15: BÜW
A16: Baulig | B16: Markus | C16: 015157940927 | D16: BA 3 | E16: =IF($A16="","",TRIM($A16&IF($B16<>"",", "&$B16,""))) -> Baulig, Markus | F16: ALV LST
A17: Uzum | C17: +4915112259736 | D17: BA 3 | E17: =IF($A17="","",TRIM($A17&IF($B17<>"",", "&$B17,""))) -> Uzum | F17: BÜW
A18: Klappert | C18: +4915112259778 | D18: BA 3 | E18: =IF($A18="","",TRIM($A18&IF($B18<>"",", "&$B18,""))) -> Klappert | F18: BÜW
A19: Theo | C19: +4915233305508 | D19: BA 3 | E19: =IF($A19="","",TRIM($A19&IF($B19<>"",", "&$B19,""))) -> Theo | F19: BÜW LSW
A20: BZL RR BA3 | B20: (Leitstelle) | C20: +4915123297056 | D20: BA 3 | E20: =IF($A20="","",TRIM($A20&IF($B20<>"",", "&$B20,""))) -> BZL RR BA3, (Leitstelle) | F20: BÜW (Leitstelle)
A21: Cüccam | B21: Aslihan | C21: +4915112259723 | D21: BA 3 | E21: =IF($A21="","",TRIM($A21&IF($B21<>"",", "&$B21,""))) -> Cüccam, Aslihan | F21: BÜW OB
A22: Eckert | C22: +4915123297056 | D22: BA 3 | E22: =IF($A22="","",TRIM($A22&IF($B22<>"",", "&$B22,""))) -> Eckert | F22: BÜW
A23: Graule | C23: +4915123297056 | D23: BA 3 | E23: =IF($A23="","",TRIM($A23&IF($B23<>"",", "&$B23,""))) -> Graule | F23: BÜW
A24: Kalchreuter | C24: +4915123297056 | D24: BA 3 | E24: =IF($A24="","",TRIM($A24&IF($B24<>"",", "&$B24,""))) -> Kalchreuter | F24: BÜW
A25: Gebel-Marloth | C25: +4915123297056 | D25: BA 3 | E25: =IF($A25="","",TRIM($A25&IF($B25<>"",", "&$B25,""))) -> Gebel-Marloth | F25: BÜW
E26: =IF($A26="","",TRIM($A26&IF($B26<>"",", "&$B26,"")))
E27: =IF($A27="","",TRIM($A27&IF($B27<>"",", "&$B27,"")))
E28: =IF($A28="","",TRIM($A28&IF($B28<>"",", "&$B28,"")))
E29: =IF($A29="","",TRIM($A29&IF($B29<>"",", "&$B29,"")))
E30: =IF($A30="","",TRIM($A30&IF($B30<>"",", "&$B30,"")))
E31: =IF($A31="","",TRIM($A31&IF($B31<>"",", "&$B31,"")))
E32: =IF($A32="","",TRIM($A32&IF($B32<>"",", "&$B32,"")))
E33: =IF($A33="","",TRIM($A33&IF($B33<>"",", "&$B33,"")))
E34: =IF($A34="","",TRIM($A34&IF($B34<>"",", "&$B34,"")))
E35: =IF($A35="","",TRIM($A35&IF($B35<>"",", "&$B35,"")))
E36: =IF($A36="","",TRIM($A36&IF($B36<>"",", "&$B36,"")))
E37: =IF($A37="","",TRIM($A37&IF($B37<>"",", "&$B37,"")))
... E80: =IF($A80="","",TRIM($A80&IF($B80<>"",", "&$B80,"")))

Sheet Streckennummern
A1: Streckennummern je Bauabschnitt
A2: Je Bauabschnitt Streckennummer und Verlauf (von – nach) eintragen. Die Nummern erscheinen automatisch als Dropdown im Feld „Streckennummer“ des passenden BA-Blatts.
A3: BA 1 | C3: BA 2 | E3: BA 3
A4: Nummer | B4: Verlauf (von – nach) | C4: Nummer | D4: Verlauf (von – nach) | E4: Nummer | F4: Verlauf (von – nach)
A5: 3507 | B5: Wiesbaden Ost – Niederlahnstein (rechte Rheinstrecke Süd); km 37,8 – 125,7 (Kilometrierung ab Frankfurt (M) Hbf) | Rüdesheim ≈ km 65, Kestert ≈ 100 | C5: 2324 | D5: Mülheim-Speldorf – Niederlahnstein (rechte Rheinstrecke Nord); km 0,95 – 154,68 | Köln-Kalk Nord ≈ km 63, Troisdorf ≈ 81,2, Neuwied ≈ 135,8 | E5: 2324 | F5: Mülheim-Speldorf – Niederlahnstein (rechte Rheinstrecke Nord); km 0,95 – 154,68 | Köln-Kalk Nord ≈ km 63, Troisdorf ≈ 81,2, Neuwied ≈ 135,8
C6: 3507 | D6: Wiesbaden Ost – Niederlahnstein (rechte Rheinstrecke Süd); km 37,8 – 125,7 (Kilometrierung ab Frankfurt (M) Hbf) | Rüdesheim ≈ km 65, Kestert ≈ 100 | E6: 3710 | F6: Wetzlar – Koblenz Hbf (Lahntalbahn); km 0,0 (Wetzlar) – 103,7 (Koblenz Hbf) | Niederlahnstein ≈ km 99–100
E7: 3011 | F7: Neuwied – Koblenz Mosel Gbf (über Urmitzer Rheinbrücke); km 0,08 – 15,37
E8: 3507 | F8: Wiesbaden Ost – Niederlahnstein (rechte Rheinstrecke Süd); km 37,8 – 125,7 (Kilometrierung ab Frankfurt (M) Hbf) | Rüdesheim ≈ km 65, Kestert ≈ 100

Sheet Gewerke & Kabeltypen
A1: Gewerke & Kabeltypen
A2: Gewerke: Einzelwerte und alle Zweier-/Dreier-Kombinationen sind vorgeneriert – Mehrfachnennung damit per Einfachklick, ganz ohne Makro. Kabeltypen: Einzelwerte in Spalte C eintragen; gewünschte Kombinationen ebenfalls als eigene Zeile anlegen (z. B. „Typ A, Typ B“). Neue Gewerke unten ergänzen – für neue Kombinationen die gewünschte Kombi als weitere Zeile eintragen.
A3: Gewerk | C3: Kabeltyp
A4: 50 Hz
A5: LST
A6: TK
A7: OSE
A8: LWL-LST
A9: LWL-TK
A10: Unbekannt
